<?xml version="1.0" encoding="utf-8"?>
<!-- =================================================================================== -->
<!-- |    This document was autogenerated by xacro from xacro/first_robot.xacro        | -->
<!-- |    EDITING THIS FILE BY HAND IS NOT RECOMMENDED                                 | -->
<!-- =================================================================================== -->
<robot name="first_robot">
  <!--A URDF (Unified Robotic Description Format) file must include the first xml version and start with a robot name.
If you are using xacro (xml+micro) to reduce the script length then, it must include the xml name space "xacro"
represented by "xmlns:xacro". http://wiki.ros.org/urdf-->
  <!--Pre-defining material properties-->
  <material name="green">
    <color rgba="0 0.8 0 1"/>
  </material>
  <!--base_link is kind of a psuedo link which not neccessary for the
robot itself but used to avoid an KDL (Kinematic and Dynamics Libraries) error. It can be named anything.-->
  <link name="odom"/>
  <!--Start of the robot description-->
  <link name="base_link">
    <visual>
      <geometry>
        <box size="0.3 0.2 0.1"/>
      </geometry>
      <material name="green"/>
    </visual>
    <!--collision is an important tag and must be included in those links which are in contact 
with the surface. It's a good practice to define collision geometry for every link.-->
    <collision>
      <geometry>
        <box size="0.3 0.2 0.1"/>
        <!--collision geometry can be of any size-->
      </geometry>
    </collision>
    <!--inertial tag is must for simulation env.-->
    <inertial>
      <mass value="3.0"/>
      <inertia ixx="0.01" ixy="0.0" ixz="0.0" iyy="0.0225" iyz="0.0" izz="0.0325"/>
    </inertial>
  </link>
  <!--Always define the body to psuedo link joint as fixed-->
  <joint name="base_to_world" type="fixed">
    <origin rpy="0.0 0.0 0.0" xyz="0.0 0.0 0.0"/>
    <parent link="odom"/>
    <child link="base_link"/>
  </joint>
  <material name="black">
    <color rgba="0 0 0 1"/>
  </material>
  <link name="right_front_wheel">
    <visual>
      <geometry>
        <cylinder length="0.02" radius="0.04"/>
      </geometry>
      <material name="black"/>
      <origin rpy="1.57075 0 0" xyz="0 0 0"/>
    </visual>
    <collision>
      <origin rpy="1.57075 0.0 0.0" xyz="0.0 0.0 0.0"/>
      <geometry>
        <cylinder length="0.02" radius="0.04"/>
      </geometry>
    </collision>
    <inertial>
      <mass value="0.2"/>
      <inertia ixx="0.00016" ixy="0.0" ixz="0.0" iyy="0.000087" iyz="0.0" izz="0.000087"/>
    </inertial>
  </link>
  <joint name="right_front_wheel_joint" type="continuous">
    <axis xyz="0.0 1.0 0.0"/>
    <parent link="base_link"/>
    <child link="right_front_wheel"/>
    <origin rpy="0.0 0.0 0.0" xyz="0.11 -0.08 -0.05"/>
  </joint>
  <!--gazebo tag is defined for gazebo environment. It is not neccessary for rviz. 
gazebo doesn't use the material defined for rviz therefore a different material  is also included.-->
  <gazebo reference="right_front_wheel">
    <mu1 value="200.0"/>
    <mu2 value="100.0"/>
    <kp value="10000000.0"/>
    <kd value="1.0"/>
    <material>Gazebo/Black</material>
  </gazebo>
  <!--The transmission element is an extension to the URDF robot description model 
that is used to describe the relationship between an actuator and a joint. http://wiki.ros.org/urdf/XML/Transmission-->
  <transmission name="right_front_wheel_trans">
    <type>transmission_interface/SimpleTransmission</type>
    <joint name="right_front_wheel_joint">
      <hardwareInterface>hardware_interface/VelocityJointInterface</hardwareInterface>
    </joint>
    <actuator name="right_front_wheel_motor">
      <mechanicalReduction>1.0</mechanicalReduction>
    </actuator>
  </transmission>
  <link name="right_back_wheel">
    <visual>
      <geometry>
        <cylinder length="0.02" radius="0.04"/>
      </geometry>
      <material name="black"/>
      <origin rpy="1.57075 0 0" xyz="0 0 0"/>
    </visual>
    <collision>
      <origin rpy="1.57075 0.0 0.0" xyz="0.0 0.0 0.0"/>
      <geometry>
        <cylinder length="0.02" radius="0.04"/>
      </geometry>
    </collision>
    <inertial>
      <mass value="0.2"/>
      <inertia ixx="0.00016" ixy="0.0" ixz="0.0" iyy="0.000087" iyz="0.0" izz="0.000087"/>
    </inertial>
  </link>
  <joint name="right_back_wheel_joint" type="continuous">
    <axis xyz="0.0 1.0 0.0"/>
    <parent link="base_link"/>
    <child link="right_back_wheel"/>
    <origin rpy="0.0 0.0 0.0" xyz="-0.11 -0.08 -0.05"/>
  </joint>
  <!--gazebo tag is defined for gazebo environment. It is not neccessary for rviz. 
gazebo doesn't use the material defined for rviz therefore a different material  is also included.-->
  <gazebo reference="right_back_wheel">
    <mu1 value="200.0"/>
    <mu2 value="100.0"/>
    <kp value="10000000.0"/>
    <kd value="1.0"/>
    <material>Gazebo/Black</material>
  </gazebo>
  <!--The transmission element is an extension to the URDF robot description model 
that is used to describe the relationship between an actuator and a joint. http://wiki.ros.org/urdf/XML/Transmission-->
  <transmission name="right_back_wheel_trans">
    <type>transmission_interface/SimpleTransmission</type>
    <joint name="right_back_wheel_joint">
      <hardwareInterface>hardware_interface/VelocityJointInterface</hardwareInterface>
    </joint>
    <actuator name="right_back_wheel_motor">
      <mechanicalReduction>1.0</mechanicalReduction>
    </actuator>
  </transmission>
  <link name="left_front_wheel">
    <visual>
      <geometry>
        <cylinder length="0.02" radius="0.04"/>
      </geometry>
      <material name="black"/>
      <origin rpy="1.57075 0 0" xyz="0 0 0"/>
    </visual>
    <collision>
      <origin rpy="1.57075 0.0 0.0" xyz="0.0 0.0 0.0"/>
      <geometry>
        <cylinder length="0.02" radius="0.04"/>
      </geometry>
    </collision>
    <inertial>
      <mass value="0.2"/>
      <inertia ixx="0.00016" ixy="0.0" ixz="0.0" iyy="0.000087" iyz="0.0" izz="0.000087"/>
    </inertial>
  </link>
  <joint name="left_front_wheel_joint" type="continuous">
    <axis xyz="0.0 1.0 0.0"/>
    <parent link="base_link"/>
    <child link="left_front_wheel"/>
    <origin rpy="0.0 0.0 0.0" xyz="0.11 0.08 -0.05"/>
  </joint>
  <!--gazebo tag is defined for gazebo environment. It is not neccessary for rviz. 
gazebo doesn't use the material defined for rviz therefore a different material  is also included.-->
  <gazebo reference="left_front_wheel">
    <mu1 value="200.0"/>
    <mu2 value="100.0"/>
    <kp value="10000000.0"/>
    <kd value="1.0"/>
    <material>Gazebo/Black</material>
  </gazebo>
  <!--The transmission element is an extension to the URDF robot description model 
that is used to describe the relationship between an actuator and a joint. http://wiki.ros.org/urdf/XML/Transmission-->
  <transmission name="left_front_wheel_trans">
    <type>transmission_interface/SimpleTransmission</type>
    <joint name="left_front_wheel_joint">
      <hardwareInterface>hardware_interface/VelocityJointInterface</hardwareInterface>
    </joint>
    <actuator name="left_front_wheel_motor">
      <mechanicalReduction>1.0</mechanicalReduction>
    </actuator>
  </transmission>
  <link name="left_back_wheel">
    <visual>
      <geometry>
        <cylinder length="0.02" radius="0.04"/>
      </geometry>
      <material name="black"/>
      <origin rpy="1.57075 0 0" xyz="0 0 0"/>
    </visual>
    <collision>
      <origin rpy="1.57075 0.0 0.0" xyz="0.0 0.0 0.0"/>
      <geometry>
        <cylinder length="0.02" radius="0.04"/>
      </geometry>
    </collision>
    <inertial>
      <mass value="0.2"/>
      <inertia ixx="0.00016" ixy="0.0" ixz="0.0" iyy="0.000087" iyz="0.0" izz="0.000087"/>
    </inertial>
  </link>
  <joint name="left_back_wheel_joint" type="continuous">
    <axis xyz="0.0 1.0 0.0"/>
    <parent link="base_link"/>
    <child link="left_back_wheel"/>
    <origin rpy="0.0 0.0 0.0" xyz="-0.11 0.08 -0.05"/>
  </joint>
  <!--gazebo tag is defined for gazebo environment. It is not neccessary for rviz. 
gazebo doesn't use the material defined for rviz therefore a different material  is also included.-->
  <gazebo reference="left_back_wheel">
    <mu1 value="200.0"/>
    <mu2 value="100.0"/>
    <kp value="10000000.0"/>
    <kd value="1.0"/>
    <material>Gazebo/Black</material>
  </gazebo>
  <!--The transmission element is an extension to the URDF robot description model 
that is used to describe the relationship between an actuator and a joint. http://wiki.ros.org/urdf/XML/Transmission-->
  <transmission name="left_back_wheel_trans">
    <type>transmission_interface/SimpleTransmission</type>
    <joint name="left_back_wheel_joint">
      <hardwareInterface>hardware_interface/VelocityJointInterface</hardwareInterface>
    </joint>
    <actuator name="left_back_wheel_motor">
      <mechanicalReduction>1.0</mechanicalReduction>
    </actuator>
  </transmission>
  <material name="white">
    <color rgba="1 1 1 1"/>
  </material>
  <link name="head">
    <visual>
      <geometry>
        <sphere radius="0.08"/>
      </geometry>
      <material name="white"/>
    </visual>
    <collision>
      <geometry>
        <sphere radius="0.08"/>
      </geometry>
    </collision>
    <inertial>
      <mass value="1.0"/>
      <inertia ixx="0.001" ixy="0.0" ixz="0.0" iyy="0.001" iyz="0.0" izz="0.001"/>
    </inertial>
  </link>
  <joint name="head_to_base_joint" type="continuous">
    <origin rpy="0.0 0.0 0.0" xyz="0.0 0.0 0.05"/>
    <parent link="base_link"/>
    <child link="head"/>
    <axis xyz="0.0 0.0 1.0"/>
  </joint>
  <transmission name="head_trans">
    <type>transmission_interface/SimpleTransmission</type>
    <joint name="head_to_base_joint">
      <hardwareInterface>hardware_interface/PositionJointInterface</hardwareInterface>
    </joint>
    <actuator name="head_motor">
      <mechanicalReduction>1.0</mechanicalReduction>
    </actuator>
  </transmission>
  <gazebo reference="base_link">
    <material>Gazebo/Green</material>
  </gazebo>
  <gazebo reference="head">
    <material>Gazebo/White</material>
  </gazebo>
  <gazebo>
    <plugin filename="libgazebo_ros_control.so" name="gazebo_ros_control">
      <robotNamespace>/first_robot</robotNamespace>
    </plugin>
  </gazebo>
</robot>
